[2024-04-18T10:31:45.412+0000] {taskinstance.py:1979} INFO - Dependencies all met for dep_context=non-requeueable deps ti=<TaskInstance: my_data_pipeline.run_tilt_data_manipulation manual__2024-04-18T10:31:41.140327+00:00 [queued]>
[2024-04-18T10:31:45.419+0000] {taskinstance.py:1979} INFO - Dependencies all met for dep_context=requeueable deps ti=<TaskInstance: my_data_pipeline.run_tilt_data_manipulation manual__2024-04-18T10:31:41.140327+00:00 [queued]>
[2024-04-18T10:31:45.420+0000] {taskinstance.py:2193} INFO - Starting attempt 1 of 3
[2024-04-18T10:31:45.433+0000] {taskinstance.py:2217} INFO - Executing <Task(PythonOperator): run_tilt_data_manipulation> on 2024-04-18 10:31:41.140327+00:00
[2024-04-18T10:31:45.440+0000] {standard_task_runner.py:60} INFO - Started process 78 to run task
[2024-04-18T10:31:45.443+0000] {standard_task_runner.py:87} INFO - Running: ['***', 'tasks', 'run', 'my_data_pipeline', 'run_tilt_data_manipulation', 'manual__2024-04-18T10:31:41.140327+00:00', '--job-id', '266', '--raw', '--subdir', 'DAGS_FOLDER/my_data_pipeline.py', '--cfg-path', '/tmp/tmpexb2u1ze']
[2024-04-18T10:31:45.444+0000] {standard_task_runner.py:88} INFO - Job 266: Subtask run_tilt_data_manipulation
[2024-04-18T10:31:45.490+0000] {task_command.py:423} INFO - Running <TaskInstance: my_data_pipeline.run_tilt_data_manipulation manual__2024-04-18T10:31:41.140327+00:00 [running]> on host d7dcc175dbab
[2024-04-18T10:31:45.568+0000] {taskinstance.py:2513} INFO - Exporting env vars: AIRFLOW_CTX_DAG_OWNER='***' AIRFLOW_CTX_DAG_ID='my_data_pipeline' AIRFLOW_CTX_TASK_ID='run_tilt_data_manipulation' AIRFLOW_CTX_EXECUTION_DATE='2024-04-18T10:31:41.140327+00:00' AIRFLOW_CTX_TRY_NUMBER='1' AIRFLOW_CTX_DAG_RUN_ID='manual__2024-04-18T10:31:41.140327+00:00'
[2024-04-18T10:31:45.571+0000] {taskinstance.py:2731} ERROR - Task failed with exception
Traceback (most recent call last):
  File "/home/airflow/.local/lib/python3.8/site-packages/airflow/models/taskinstance.py", line 444, in _execute_task
    result = _execute_callable(context=context, **execute_callable_kwargs)
  File "/home/airflow/.local/lib/python3.8/site-packages/airflow/models/taskinstance.py", line 414, in _execute_callable
    return execute_callable(context=context, **execute_callable_kwargs)
  File "/home/airflow/.local/lib/python3.8/site-packages/airflow/operators/python.py", line 200, in execute
    return_value = self.execute_callable()
  File "/home/airflow/.local/lib/python3.8/site-packages/airflow/operators/python.py", line 217, in execute_callable
    return self.python_callable(*self.op_args, **self.op_kwargs)
  File "/opt/airflow/plugins/Tdata_manipulation.py", line 6, in main
    with open('TILT_DATA.txt', 'r') as file:
FileNotFoundError: [Errno 2] No such file or directory: 'TILT_DATA.txt'
[2024-04-18T10:31:45.588+0000] {taskinstance.py:1149} INFO - Marking task as UP_FOR_RETRY. dag_id=my_data_pipeline, task_id=run_tilt_data_manipulation, execution_date=20240418T103141, start_date=20240418T103145, end_date=20240418T103145
[2024-04-18T10:31:45.598+0000] {standard_task_runner.py:107} ERROR - Failed to execute job 266 for task run_tilt_data_manipulation ([Errno 2] No such file or directory: 'TILT_DATA.txt'; 78)
[2024-04-18T10:31:45.616+0000] {local_task_job_runner.py:234} INFO - Task exited with return code 1
[2024-04-18T10:31:45.632+0000] {taskinstance.py:3312} INFO - 0 downstream tasks scheduled from follow-on schedule check
