[2024-04-02T20:20:52.979+0000] {taskinstance.py:1979} INFO - Dependencies all met for dep_context=non-requeueable deps ti=<TaskInstance: my_data_pipeline.run_data_manipulation manual__2024-04-02T20:10:45.468504+00:00 [queued]>
[2024-04-02T20:20:52.991+0000] {taskinstance.py:1979} INFO - Dependencies all met for dep_context=requeueable deps ti=<TaskInstance: my_data_pipeline.run_data_manipulation manual__2024-04-02T20:10:45.468504+00:00 [queued]>
[2024-04-02T20:20:52.992+0000] {taskinstance.py:2193} INFO - Starting attempt 3 of 3
[2024-04-02T20:20:53.007+0000] {taskinstance.py:2217} INFO - Executing <Task(PythonOperator): run_data_manipulation> on 2024-04-02 20:10:45.468504+00:00
[2024-04-02T20:20:53.013+0000] {standard_task_runner.py:60} INFO - Started process 322 to run task
[2024-04-02T20:20:53.017+0000] {standard_task_runner.py:87} INFO - Running: ['***', 'tasks', 'run', 'my_data_pipeline', 'run_data_manipulation', 'manual__2024-04-02T20:10:45.468504+00:00', '--job-id', '40', '--raw', '--subdir', 'DAGS_FOLDER/my_data_pipeline.py', '--cfg-path', '/tmp/tmphu7aq41b']
[2024-04-02T20:20:53.019+0000] {standard_task_runner.py:88} INFO - Job 40: Subtask run_data_manipulation
[2024-04-02T20:20:53.068+0000] {task_command.py:423} INFO - Running <TaskInstance: my_data_pipeline.run_data_manipulation manual__2024-04-02T20:10:45.468504+00:00 [running]> on host 59ad83643d53
[2024-04-02T20:20:53.149+0000] {taskinstance.py:2513} INFO - Exporting env vars: AIRFLOW_CTX_DAG_OWNER='***' AIRFLOW_CTX_DAG_ID='my_data_pipeline' AIRFLOW_CTX_TASK_ID='run_data_manipulation' AIRFLOW_CTX_EXECUTION_DATE='2024-04-02T20:10:45.468504+00:00' AIRFLOW_CTX_TRY_NUMBER='3' AIRFLOW_CTX_DAG_RUN_ID='manual__2024-04-02T20:10:45.468504+00:00'
[2024-04-02T20:20:53.154+0000] {taskinstance.py:2731} ERROR - Task failed with exception
Traceback (most recent call last):
  File "/home/airflow/.local/lib/python3.8/site-packages/airflow/models/taskinstance.py", line 444, in _execute_task
    result = _execute_callable(context=context, **execute_callable_kwargs)
  File "/home/airflow/.local/lib/python3.8/site-packages/airflow/models/taskinstance.py", line 414, in _execute_callable
    return execute_callable(context=context, **execute_callable_kwargs)
  File "/home/airflow/.local/lib/python3.8/site-packages/airflow/operators/python.py", line 200, in execute
    return_value = self.execute_callable()
  File "/home/airflow/.local/lib/python3.8/site-packages/airflow/operators/python.py", line 217, in execute_callable
    return self.python_callable(*self.op_args, **self.op_kwargs)
  File "/opt/airflow/plugins/data_manipulation.py", line 29, in main
    df1 = pd.read_csv("KPI Analysis Result_Query_Result_20240325102721558(KPI Analysis Result).csv", encoding='latin1', skiprows=6)
  File "/home/airflow/.local/lib/python3.8/site-packages/pandas/io/parsers/readers.py", line 912, in read_csv
    return _read(filepath_or_buffer, kwds)
  File "/home/airflow/.local/lib/python3.8/site-packages/pandas/io/parsers/readers.py", line 577, in _read
    parser = TextFileReader(filepath_or_buffer, **kwds)
  File "/home/airflow/.local/lib/python3.8/site-packages/pandas/io/parsers/readers.py", line 1407, in __init__
    self._engine = self._make_engine(f, self.engine)
  File "/home/airflow/.local/lib/python3.8/site-packages/pandas/io/parsers/readers.py", line 1661, in _make_engine
    self.handles = get_handle(
  File "/home/airflow/.local/lib/python3.8/site-packages/pandas/io/common.py", line 859, in get_handle
    handle = open(
FileNotFoundError: [Errno 2] No such file or directory: 'KPI Analysis Result_Query_Result_20240325102721558(KPI Analysis Result).csv'
[2024-04-02T20:20:53.174+0000] {taskinstance.py:1149} INFO - Marking task as FAILED. dag_id=my_data_pipeline, task_id=run_data_manipulation, execution_date=20240402T201045, start_date=20240402T202052, end_date=20240402T202053
[2024-04-02T20:20:53.188+0000] {standard_task_runner.py:107} ERROR - Failed to execute job 40 for task run_data_manipulation ([Errno 2] No such file or directory: 'KPI Analysis Result_Query_Result_20240325102721558(KPI Analysis Result).csv'; 322)
[2024-04-02T20:20:53.232+0000] {local_task_job_runner.py:234} INFO - Task exited with return code 1
[2024-04-02T20:20:53.249+0000] {taskinstance.py:3312} INFO - 0 downstream tasks scheduled from follow-on schedule check
