[2024-04-19T13:12:54.890+0000] {taskinstance.py:1979} INFO - Dependencies all met for dep_context=non-requeueable deps ti=<TaskInstance: my_data_pipeline.run_power_data_manipulation manual__2024-04-19T13:07:48.261340+00:00 [queued]>
[2024-04-19T13:12:54.897+0000] {taskinstance.py:1979} INFO - Dependencies all met for dep_context=requeueable deps ti=<TaskInstance: my_data_pipeline.run_power_data_manipulation manual__2024-04-19T13:07:48.261340+00:00 [queued]>
[2024-04-19T13:12:54.898+0000] {taskinstance.py:2193} INFO - Starting attempt 2 of 3
[2024-04-19T13:12:54.916+0000] {taskinstance.py:2217} INFO - Executing <Task(PythonOperator): run_power_data_manipulation> on 2024-04-19 13:07:48.261340+00:00
[2024-04-19T13:12:54.924+0000] {standard_task_runner.py:60} INFO - Started process 160 to run task
[2024-04-19T13:12:54.927+0000] {standard_task_runner.py:87} INFO - Running: ['***', 'tasks', 'run', 'my_data_pipeline', 'run_power_data_manipulation', 'manual__2024-04-19T13:07:48.261340+00:00', '--job-id', '288', '--raw', '--subdir', 'DAGS_FOLDER/my_data_pipeline.py', '--cfg-path', '/tmp/tmpp393t40_']
[2024-04-19T13:12:54.929+0000] {standard_task_runner.py:88} INFO - Job 288: Subtask run_power_data_manipulation
[2024-04-19T13:12:54.978+0000] {task_command.py:423} INFO - Running <TaskInstance: my_data_pipeline.run_power_data_manipulation manual__2024-04-19T13:07:48.261340+00:00 [running]> on host 6bf7a091397a
[2024-04-19T13:12:55.074+0000] {taskinstance.py:2513} INFO - Exporting env vars: AIRFLOW_CTX_DAG_OWNER='***' AIRFLOW_CTX_DAG_ID='my_data_pipeline' AIRFLOW_CTX_TASK_ID='run_power_data_manipulation' AIRFLOW_CTX_EXECUTION_DATE='2024-04-19T13:07:48.261340+00:00' AIRFLOW_CTX_TRY_NUMBER='2' AIRFLOW_CTX_DAG_RUN_ID='manual__2024-04-19T13:07:48.261340+00:00'
[2024-04-19T13:12:55.077+0000] {taskinstance.py:2731} ERROR - Task failed with exception
Traceback (most recent call last):
  File "/home/airflow/.local/lib/python3.8/site-packages/airflow/models/taskinstance.py", line 444, in _execute_task
    result = _execute_callable(context=context, **execute_callable_kwargs)
  File "/home/airflow/.local/lib/python3.8/site-packages/airflow/models/taskinstance.py", line 414, in _execute_callable
    return execute_callable(context=context, **execute_callable_kwargs)
  File "/home/airflow/.local/lib/python3.8/site-packages/airflow/operators/python.py", line 200, in execute
    return_value = self.execute_callable()
  File "/home/airflow/.local/lib/python3.8/site-packages/airflow/operators/python.py", line 217, in execute_callable
    return self.python_callable(*self.op_args, **self.op_kwargs)
  File "/opt/airflow/plugins/Pdata_manipulation.py", line 141, in main
    with open('POWER_DATA.txt', 'r') as f:
FileNotFoundError: [Errno 2] No such file or directory: 'POWER_DATA.txt'
[2024-04-19T13:12:55.098+0000] {taskinstance.py:1149} INFO - Marking task as UP_FOR_RETRY. dag_id=my_data_pipeline, task_id=run_power_data_manipulation, execution_date=20240419T130748, start_date=20240419T131254, end_date=20240419T131255
[2024-04-19T13:12:55.112+0000] {standard_task_runner.py:107} ERROR - Failed to execute job 288 for task run_power_data_manipulation ([Errno 2] No such file or directory: 'POWER_DATA.txt'; 160)
[2024-04-19T13:12:55.141+0000] {local_task_job_runner.py:234} INFO - Task exited with return code 1
[2024-04-19T13:12:55.164+0000] {taskinstance.py:3312} INFO - 0 downstream tasks scheduled from follow-on schedule check
