[2024-04-08T07:55:51.837+0000] {taskinstance.py:1979} INFO - Dependencies all met for dep_context=non-requeueable deps ti=<TaskInstance: my_data_pipeline.run_data_manipulation scheduled__2024-04-07T00:00:00+00:00 [queued]>
[2024-04-08T07:55:51.863+0000] {taskinstance.py:1979} INFO - Dependencies all met for dep_context=requeueable deps ti=<TaskInstance: my_data_pipeline.run_data_manipulation scheduled__2024-04-07T00:00:00+00:00 [queued]>
[2024-04-08T07:55:51.864+0000] {taskinstance.py:2193} INFO - Starting attempt 1 of 3
[2024-04-08T07:55:51.900+0000] {taskinstance.py:2217} INFO - Executing <Task(PythonOperator): run_data_manipulation> on 2024-04-07 00:00:00+00:00
[2024-04-08T07:55:51.913+0000] {standard_task_runner.py:60} INFO - Started process 71 to run task
[2024-04-08T07:55:51.921+0000] {standard_task_runner.py:87} INFO - Running: ['***', 'tasks', 'run', 'my_data_pipeline', 'run_data_manipulation', 'scheduled__2024-04-07T00:00:00+00:00', '--job-id', '210', '--raw', '--subdir', 'DAGS_FOLDER/my_data_pipeline.py', '--cfg-path', '/tmp/tmp7dsbjay4']
[2024-04-08T07:55:51.924+0000] {standard_task_runner.py:88} INFO - Job 210: Subtask run_data_manipulation
[2024-04-08T07:55:52.048+0000] {task_command.py:423} INFO - Running <TaskInstance: my_data_pipeline.run_data_manipulation scheduled__2024-04-07T00:00:00+00:00 [running]> on host 4834387948e7
[2024-04-08T07:55:52.383+0000] {taskinstance.py:2513} INFO - Exporting env vars: AIRFLOW_CTX_DAG_OWNER='***' AIRFLOW_CTX_DAG_ID='my_data_pipeline' AIRFLOW_CTX_TASK_ID='run_data_manipulation' AIRFLOW_CTX_EXECUTION_DATE='2024-04-07T00:00:00+00:00' AIRFLOW_CTX_TRY_NUMBER='1' AIRFLOW_CTX_DAG_RUN_ID='scheduled__2024-04-07T00:00:00+00:00'
[2024-04-08T07:55:52.391+0000] {taskinstance.py:2731} ERROR - Task failed with exception
Traceback (most recent call last):
  File "/home/airflow/.local/lib/python3.8/site-packages/airflow/models/taskinstance.py", line 444, in _execute_task
    result = _execute_callable(context=context, **execute_callable_kwargs)
  File "/home/airflow/.local/lib/python3.8/site-packages/airflow/models/taskinstance.py", line 414, in _execute_callable
    return execute_callable(context=context, **execute_callable_kwargs)
  File "/home/airflow/.local/lib/python3.8/site-packages/airflow/operators/python.py", line 200, in execute
    return_value = self.execute_callable()
  File "/home/airflow/.local/lib/python3.8/site-packages/airflow/operators/python.py", line 217, in execute_callable
    return self.python_callable(*self.op_args, **self.op_kwargs)
  File "/opt/airflow/plugins/data_manipulation.py", line 33, in main
    df1 = pd.read_csv(csv_file_path, encoding='latin1', skiprows=6)
  File "/home/airflow/.local/lib/python3.8/site-packages/pandas/io/parsers/readers.py", line 912, in read_csv
    return _read(filepath_or_buffer, kwds)
  File "/home/airflow/.local/lib/python3.8/site-packages/pandas/io/parsers/readers.py", line 577, in _read
    parser = TextFileReader(filepath_or_buffer, **kwds)
  File "/home/airflow/.local/lib/python3.8/site-packages/pandas/io/parsers/readers.py", line 1407, in __init__
    self._engine = self._make_engine(f, self.engine)
  File "/home/airflow/.local/lib/python3.8/site-packages/pandas/io/parsers/readers.py", line 1661, in _make_engine
    self.handles = get_handle(
  File "/home/airflow/.local/lib/python3.8/site-packages/pandas/io/common.py", line 859, in get_handle
    handle = open(
FileNotFoundError: [Errno 2] No such file or directory: '/host_data/KPI Analysis Result_Query_Result_20240325102721558(KPI Analysis Result).csv'
[2024-04-08T07:55:52.444+0000] {taskinstance.py:1149} INFO - Marking task as UP_FOR_RETRY. dag_id=my_data_pipeline, task_id=run_data_manipulation, execution_date=20240407T000000, start_date=20240408T075551, end_date=20240408T075552
[2024-04-08T07:55:52.505+0000] {standard_task_runner.py:107} ERROR - Failed to execute job 210 for task run_data_manipulation ([Errno 2] No such file or directory: '/host_data/KPI Analysis Result_Query_Result_20240325102721558(KPI Analysis Result).csv'; 71)
[2024-04-08T07:55:52.539+0000] {local_task_job_runner.py:234} INFO - Task exited with return code 1
[2024-04-08T07:55:52.586+0000] {taskinstance.py:3312} INFO - 0 downstream tasks scheduled from follow-on schedule check
