[2024-04-19T13:45:55.910+0000] {taskinstance.py:1979} INFO - Dependencies all met for dep_context=non-requeueable deps ti=<TaskInstance: my_data_pipeline.run_power_data_manipulation manual__2024-04-19T13:40:50.292561+00:00 [queued]>
[2024-04-19T13:45:55.916+0000] {taskinstance.py:1979} INFO - Dependencies all met for dep_context=requeueable deps ti=<TaskInstance: my_data_pipeline.run_power_data_manipulation manual__2024-04-19T13:40:50.292561+00:00 [queued]>
[2024-04-19T13:45:55.917+0000] {taskinstance.py:2193} INFO - Starting attempt 2 of 3
[2024-04-19T13:45:55.927+0000] {taskinstance.py:2217} INFO - Executing <Task(PythonOperator): run_power_data_manipulation> on 2024-04-19 13:40:50.292561+00:00
[2024-04-19T13:45:55.932+0000] {standard_task_runner.py:60} INFO - Started process 153 to run task
[2024-04-19T13:45:55.935+0000] {standard_task_runner.py:87} INFO - Running: ['***', 'tasks', 'run', 'my_data_pipeline', 'run_power_data_manipulation', 'manual__2024-04-19T13:40:50.292561+00:00', '--job-id', '305', '--raw', '--subdir', 'DAGS_FOLDER/my_data_pipeline.py', '--cfg-path', '/tmp/tmpn5zzmjmn']
[2024-04-19T13:45:55.936+0000] {standard_task_runner.py:88} INFO - Job 305: Subtask run_power_data_manipulation
[2024-04-19T13:45:55.978+0000] {task_command.py:423} INFO - Running <TaskInstance: my_data_pipeline.run_power_data_manipulation manual__2024-04-19T13:40:50.292561+00:00 [running]> on host f9377ff7a6f7
[2024-04-19T13:45:56.041+0000] {taskinstance.py:2513} INFO - Exporting env vars: AIRFLOW_CTX_DAG_OWNER='***' AIRFLOW_CTX_DAG_ID='my_data_pipeline' AIRFLOW_CTX_TASK_ID='run_power_data_manipulation' AIRFLOW_CTX_EXECUTION_DATE='2024-04-19T13:40:50.292561+00:00' AIRFLOW_CTX_TRY_NUMBER='2' AIRFLOW_CTX_DAG_RUN_ID='manual__2024-04-19T13:40:50.292561+00:00'
[2024-04-19T13:45:56.043+0000] {taskinstance.py:2731} ERROR - Task failed with exception
Traceback (most recent call last):
  File "/home/airflow/.local/lib/python3.8/site-packages/airflow/models/taskinstance.py", line 444, in _execute_task
    result = _execute_callable(context=context, **execute_callable_kwargs)
  File "/home/airflow/.local/lib/python3.8/site-packages/airflow/models/taskinstance.py", line 414, in _execute_callable
    return execute_callable(context=context, **execute_callable_kwargs)
  File "/home/airflow/.local/lib/python3.8/site-packages/airflow/operators/python.py", line 200, in execute
    return_value = self.execute_callable()
  File "/home/airflow/.local/lib/python3.8/site-packages/airflow/operators/python.py", line 217, in execute_callable
    return self.python_callable(*self.op_args, **self.op_kwargs)
  File "/opt/airflow/plugins/Pdata_manipulation.py", line 20, in main
    with open('POWER_DATA.txt', 'r') as f:
FileNotFoundError: [Errno 2] No such file or directory: 'POWER_DATA.txt'
[2024-04-19T13:45:56.055+0000] {taskinstance.py:1149} INFO - Marking task as UP_FOR_RETRY. dag_id=my_data_pipeline, task_id=run_power_data_manipulation, execution_date=20240419T134050, start_date=20240419T134555, end_date=20240419T134556
[2024-04-19T13:45:56.065+0000] {standard_task_runner.py:107} ERROR - Failed to execute job 305 for task run_power_data_manipulation ([Errno 2] No such file or directory: 'POWER_DATA.txt'; 153)
[2024-04-19T13:45:56.108+0000] {local_task_job_runner.py:234} INFO - Task exited with return code 1
[2024-04-19T13:45:56.125+0000] {taskinstance.py:3312} INFO - 0 downstream tasks scheduled from follow-on schedule check
