[2024-04-08T10:04:47.655+0000] {taskinstance.py:1979} INFO - Dependencies all met for dep_context=non-requeueable deps ti=<TaskInstance: my_data_pipeline.run_data_manipulation manual__2024-04-08T09:49:40.150692+00:00 [queued]>
[2024-04-08T10:04:47.661+0000] {taskinstance.py:1979} INFO - Dependencies all met for dep_context=requeueable deps ti=<TaskInstance: my_data_pipeline.run_data_manipulation manual__2024-04-08T09:49:40.150692+00:00 [queued]>
[2024-04-08T10:04:47.662+0000] {taskinstance.py:2193} INFO - Starting attempt 4 of 4
[2024-04-08T10:04:47.675+0000] {taskinstance.py:2217} INFO - Executing <Task(PythonOperator): run_data_manipulation> on 2024-04-08 09:49:40.150692+00:00
[2024-04-08T10:04:47.680+0000] {standard_task_runner.py:60} INFO - Started process 302 to run task
[2024-04-08T10:04:47.682+0000] {standard_task_runner.py:87} INFO - Running: ['***', 'tasks', 'run', 'my_data_pipeline', 'run_data_manipulation', 'manual__2024-04-08T09:49:40.150692+00:00', '--job-id', '235', '--raw', '--subdir', 'DAGS_FOLDER/my_data_pipeline.py', '--cfg-path', '/tmp/tmpgyeqo5mq']
[2024-04-08T10:04:47.683+0000] {standard_task_runner.py:88} INFO - Job 235: Subtask run_data_manipulation
[2024-04-08T10:04:47.726+0000] {task_command.py:423} INFO - Running <TaskInstance: my_data_pipeline.run_data_manipulation manual__2024-04-08T09:49:40.150692+00:00 [running]> on host 9075ddca632b
[2024-04-08T10:04:47.790+0000] {taskinstance.py:2513} INFO - Exporting env vars: AIRFLOW_CTX_DAG_OWNER='***' AIRFLOW_CTX_DAG_ID='my_data_pipeline' AIRFLOW_CTX_TASK_ID='run_data_manipulation' AIRFLOW_CTX_EXECUTION_DATE='2024-04-08T09:49:40.150692+00:00' AIRFLOW_CTX_TRY_NUMBER='4' AIRFLOW_CTX_DAG_RUN_ID='manual__2024-04-08T09:49:40.150692+00:00'
[2024-04-08T10:04:47.791+0000] {taskinstance.py:2731} ERROR - Task failed with exception
Traceback (most recent call last):
  File "/home/airflow/.local/lib/python3.8/site-packages/airflow/models/taskinstance.py", line 444, in _execute_task
    result = _execute_callable(context=context, **execute_callable_kwargs)
  File "/home/airflow/.local/lib/python3.8/site-packages/airflow/models/taskinstance.py", line 414, in _execute_callable
    return execute_callable(context=context, **execute_callable_kwargs)
  File "/home/airflow/.local/lib/python3.8/site-packages/airflow/operators/python.py", line 200, in execute
    return_value = self.execute_callable()
  File "/home/airflow/.local/lib/python3.8/site-packages/airflow/operators/python.py", line 217, in execute_callable
    return self.python_callable(*self.op_args, **self.op_kwargs)
  File "/opt/airflow/dags/my_data_pipeline.py", line 32, in run_data_manipulation
    raise ValueError("Intentional error for testing")
ValueError: Intentional error for testing
[2024-04-08T10:04:47.803+0000] {taskinstance.py:1149} INFO - Marking task as FAILED. dag_id=my_data_pipeline, task_id=run_data_manipulation, execution_date=20240408T094940, start_date=20240408T100447, end_date=20240408T100447
[2024-04-08T10:04:47.804+0000] {logging_mixin.py:188} INFO - Task run_data_manipulation failed with error: Intentional error for testing
[2024-04-08T10:04:47.813+0000] {standard_task_runner.py:107} ERROR - Failed to execute job 235 for task run_data_manipulation (Intentional error for testing; 302)
[2024-04-08T10:04:47.855+0000] {local_task_job_runner.py:234} INFO - Task exited with return code 1
[2024-04-08T10:04:47.870+0000] {taskinstance.py:3312} INFO - 0 downstream tasks scheduled from follow-on schedule check
