[2024-04-02T22:48:46.445+0000] {taskinstance.py:1979} INFO - Dependencies all met for dep_context=non-requeueable deps ti=<TaskInstance: my_data_pipeline.run_data_manipulation manual__2024-04-02T22:38:38.397527+00:00 [queued]>
[2024-04-02T22:48:46.455+0000] {taskinstance.py:1979} INFO - Dependencies all met for dep_context=requeueable deps ti=<TaskInstance: my_data_pipeline.run_data_manipulation manual__2024-04-02T22:38:38.397527+00:00 [queued]>
[2024-04-02T22:48:46.456+0000] {taskinstance.py:2193} INFO - Starting attempt 3 of 3
[2024-04-02T22:48:46.470+0000] {taskinstance.py:2217} INFO - Executing <Task(PythonOperator): run_data_manipulation> on 2024-04-02 22:38:38.397527+00:00
[2024-04-02T22:48:46.475+0000] {standard_task_runner.py:60} INFO - Started process 259 to run task
[2024-04-02T22:48:46.480+0000] {standard_task_runner.py:87} INFO - Running: ['***', 'tasks', 'run', 'my_data_pipeline', 'run_data_manipulation', 'manual__2024-04-02T22:38:38.397527+00:00', '--job-id', '52', '--raw', '--subdir', 'DAGS_FOLDER/my_data_pipeline.py', '--cfg-path', '/tmp/tmpdziogauq']
[2024-04-02T22:48:46.481+0000] {standard_task_runner.py:88} INFO - Job 52: Subtask run_data_manipulation
[2024-04-02T22:48:46.530+0000] {task_command.py:423} INFO - Running <TaskInstance: my_data_pipeline.run_data_manipulation manual__2024-04-02T22:38:38.397527+00:00 [running]> on host 6a173df11d1f
[2024-04-02T22:48:46.603+0000] {taskinstance.py:2513} INFO - Exporting env vars: AIRFLOW_CTX_DAG_OWNER='***' AIRFLOW_CTX_DAG_ID='my_data_pipeline' AIRFLOW_CTX_TASK_ID='run_data_manipulation' AIRFLOW_CTX_EXECUTION_DATE='2024-04-02T22:38:38.397527+00:00' AIRFLOW_CTX_TRY_NUMBER='3' AIRFLOW_CTX_DAG_RUN_ID='manual__2024-04-02T22:38:38.397527+00:00'
[2024-04-02T22:48:46.609+0000] {taskinstance.py:2731} ERROR - Task failed with exception
Traceback (most recent call last):
  File "/home/airflow/.local/lib/python3.8/site-packages/airflow/models/taskinstance.py", line 444, in _execute_task
    result = _execute_callable(context=context, **execute_callable_kwargs)
  File "/home/airflow/.local/lib/python3.8/site-packages/airflow/models/taskinstance.py", line 414, in _execute_callable
    return execute_callable(context=context, **execute_callable_kwargs)
  File "/home/airflow/.local/lib/python3.8/site-packages/airflow/operators/python.py", line 200, in execute
    return_value = self.execute_callable()
  File "/home/airflow/.local/lib/python3.8/site-packages/airflow/operators/python.py", line 217, in execute_callable
    return self.python_callable(*self.op_args, **self.op_kwargs)
  File "/opt/airflow/plugins/data_manipulation.py", line 33, in main
    df1 = pd.read_csv(csv_file_path, encoding='latin1', skiprows=6)
  File "/home/airflow/.local/lib/python3.8/site-packages/pandas/io/parsers/readers.py", line 912, in read_csv
    return _read(filepath_or_buffer, kwds)
  File "/home/airflow/.local/lib/python3.8/site-packages/pandas/io/parsers/readers.py", line 577, in _read
    parser = TextFileReader(filepath_or_buffer, **kwds)
  File "/home/airflow/.local/lib/python3.8/site-packages/pandas/io/parsers/readers.py", line 1407, in __init__
    self._engine = self._make_engine(f, self.engine)
  File "/home/airflow/.local/lib/python3.8/site-packages/pandas/io/parsers/readers.py", line 1661, in _make_engine
    self.handles = get_handle(
  File "/home/airflow/.local/lib/python3.8/site-packages/pandas/io/common.py", line 859, in get_handle
    handle = open(
FileNotFoundError: [Errno 2] No such file or directory: '/opt/airflow/KPI Analysis Result_Query_Result_20240325102721558(KPI Analysis Result).csv'
[2024-04-02T22:48:46.637+0000] {taskinstance.py:1149} INFO - Marking task as FAILED. dag_id=my_data_pipeline, task_id=run_data_manipulation, execution_date=20240402T223838, start_date=20240402T224846, end_date=20240402T224846
[2024-04-02T22:48:46.649+0000] {standard_task_runner.py:107} ERROR - Failed to execute job 52 for task run_data_manipulation ([Errno 2] No such file or directory: '/opt/airflow/KPI Analysis Result_Query_Result_20240325102721558(KPI Analysis Result).csv'; 259)
[2024-04-02T22:48:46.692+0000] {local_task_job_runner.py:234} INFO - Task exited with return code 1
[2024-04-02T22:48:46.718+0000] {taskinstance.py:3312} INFO - 0 downstream tasks scheduled from follow-on schedule check
