[2024-04-02T22:27:38.776+0000] {taskinstance.py:1979} INFO - Dependencies all met for dep_context=non-requeueable deps ti=<TaskInstance: my_data_pipeline.run_data_manipulation manual__2024-04-02T22:22:32.154720+00:00 [queued]>
[2024-04-02T22:27:38.787+0000] {taskinstance.py:1979} INFO - Dependencies all met for dep_context=requeueable deps ti=<TaskInstance: my_data_pipeline.run_data_manipulation manual__2024-04-02T22:22:32.154720+00:00 [queued]>
[2024-04-02T22:27:38.788+0000] {taskinstance.py:2193} INFO - Starting attempt 2 of 3
[2024-04-02T22:27:38.805+0000] {taskinstance.py:2217} INFO - Executing <Task(PythonOperator): run_data_manipulation> on 2024-04-02 22:22:32.154720+00:00
[2024-04-02T22:27:38.811+0000] {standard_task_runner.py:60} INFO - Started process 61 to run task
[2024-04-02T22:27:38.815+0000] {standard_task_runner.py:87} INFO - Running: ['***', 'tasks', 'run', 'my_data_pipeline', 'run_data_manipulation', 'manual__2024-04-02T22:22:32.154720+00:00', '--job-id', '46', '--raw', '--subdir', 'DAGS_FOLDER/my_data_pipeline.py', '--cfg-path', '/tmp/tmpx46xget1']
[2024-04-02T22:27:38.817+0000] {standard_task_runner.py:88} INFO - Job 46: Subtask run_data_manipulation
[2024-04-02T22:27:38.882+0000] {task_command.py:423} INFO - Running <TaskInstance: my_data_pipeline.run_data_manipulation manual__2024-04-02T22:22:32.154720+00:00 [running]> on host adb02c284dc4
[2024-04-02T22:27:38.964+0000] {taskinstance.py:2513} INFO - Exporting env vars: AIRFLOW_CTX_DAG_OWNER='***' AIRFLOW_CTX_DAG_ID='my_data_pipeline' AIRFLOW_CTX_TASK_ID='run_data_manipulation' AIRFLOW_CTX_EXECUTION_DATE='2024-04-02T22:22:32.154720+00:00' AIRFLOW_CTX_TRY_NUMBER='2' AIRFLOW_CTX_DAG_RUN_ID='manual__2024-04-02T22:22:32.154720+00:00'
[2024-04-02T22:27:38.971+0000] {taskinstance.py:2731} ERROR - Task failed with exception
Traceback (most recent call last):
  File "/home/airflow/.local/lib/python3.8/site-packages/airflow/models/taskinstance.py", line 444, in _execute_task
    result = _execute_callable(context=context, **execute_callable_kwargs)
  File "/home/airflow/.local/lib/python3.8/site-packages/airflow/models/taskinstance.py", line 414, in _execute_callable
    return execute_callable(context=context, **execute_callable_kwargs)
  File "/home/airflow/.local/lib/python3.8/site-packages/airflow/operators/python.py", line 200, in execute
    return_value = self.execute_callable()
  File "/home/airflow/.local/lib/python3.8/site-packages/airflow/operators/python.py", line 217, in execute_callable
    return self.python_callable(*self.op_args, **self.op_kwargs)
  File "/opt/airflow/plugins/data_manipulation.py", line 33, in main
    df1 = pd.read_csv(csv_file_path, encoding='latin1', skiprows=6)
  File "/home/airflow/.local/lib/python3.8/site-packages/pandas/io/parsers/readers.py", line 912, in read_csv
    return _read(filepath_or_buffer, kwds)
  File "/home/airflow/.local/lib/python3.8/site-packages/pandas/io/parsers/readers.py", line 577, in _read
    parser = TextFileReader(filepath_or_buffer, **kwds)
  File "/home/airflow/.local/lib/python3.8/site-packages/pandas/io/parsers/readers.py", line 1407, in __init__
    self._engine = self._make_engine(f, self.engine)
  File "/home/airflow/.local/lib/python3.8/site-packages/pandas/io/parsers/readers.py", line 1661, in _make_engine
    self.handles = get_handle(
  File "/home/airflow/.local/lib/python3.8/site-packages/pandas/io/common.py", line 859, in get_handle
    handle = open(
FileNotFoundError: [Errno 2] No such file or directory: '/host_data/KPI Analysis Result_Query_Result_20240325102721558(KPI Analysis Result).csv'
[2024-04-02T22:27:38.990+0000] {taskinstance.py:1149} INFO - Marking task as UP_FOR_RETRY. dag_id=my_data_pipeline, task_id=run_data_manipulation, execution_date=20240402T222232, start_date=20240402T222738, end_date=20240402T222738
[2024-04-02T22:27:39.005+0000] {standard_task_runner.py:107} ERROR - Failed to execute job 46 for task run_data_manipulation ([Errno 2] No such file or directory: '/host_data/KPI Analysis Result_Query_Result_20240325102721558(KPI Analysis Result).csv'; 61)
[2024-04-02T22:27:39.030+0000] {local_task_job_runner.py:234} INFO - Task exited with return code 1
[2024-04-02T22:27:39.059+0000] {taskinstance.py:3312} INFO - 0 downstream tasks scheduled from follow-on schedule check
